Workbook

Sheet Legend
A1: Euclidian Categories | B1: Descriptor
A2: River_dist | B2: Distance in metres from the site to the neares water stream (watre streams from HydroRIVERS, Project -provider: HydroSHEDS)
A3: Road_dist | B3: Distance in metres from the site to the nearest Roman road (roads from Itiner-e)
A4: Near_500 | B4: Distance in metres from the site to the nearest DEM-derived drainage line extracted with a flow accumulation threshold of 500
A5: Near_750 | B5: Distance in metres from the site to the nearest DEM-derived drainage line extracted with a flow accumulation threshold of 750
A6: Near_1000 | B6: Distance in metres from the site to the nearest DEM-derived drainage line extracted with a flow accumulation threshold of 1000
A7: Near_3000 | B7: Distance in metres from the site to the nearest DEM-derived drainage line extracted with a flow accumulation threshold of 3000
A10: Geology and agricultural potential legend
A11: Code | B11: Full FAO soil name | C11: Soil group | D11: Main limitation / trait | E11: Agricultural potential | F11: Potential score | H11: Code | I11: Landform | J11: Agricultural potential | K11: Potential score
A12: FLe | B12: Eutric Fluvisols | C12: Fluvisol | D12: Alluvial soil; generally fertile | E12: High | F12: 4 | H12: LV | I12: Valley floor | J12: High | K12: 4
A13: CLl | B13: Luvic Calcisols | C13: Calcisol | D13: Calcareous soil with clay accumulation | E13: Moderate | F13: 3 | H13: LP | I13: Plain | J13: Moderate-high | K13: 3
A14: CLh | B14: Haplic Calcisols | C14: Calcisol | D14: Calcareous soil | E14: Moderate | F14: 3 | H14: LD | I14: Depression | J14: Low-moderate | K14: 2
A15: CMc | B15: Calcaric Cambisols | C15: Cambisol | D15: Moderately developed calcareous soil | E15: Moderate | F15: 3 | H15: SH | I15: Medium hill | J15: Low | K15: 1
A16: GLe | B16: Eutric Gleysols | C16: Gleysol | D16: Poor drainage / waterlogging | E16: Low | F16: 2
A17: CLp | B17: Petric Calcisols | C17: Calcisol | D17: Petrocalcic hardpan / restricted rooting | E17: Low | F17: 2
A18: SNk | B18: Calcic Solonetz | C18: Solonetz | D18: Sodicity / structural constraint | E18: Very low | F18: 1
A19: SCn | B19: Sodic Solonchaks | C19: Solonchak | D19: Salinity and sodicity | E19: Very low | F19: 1
A20: *U-H | C20: Unconsolidated sedimentary aquifer | E20: High productivity | F20: 4
A21: *CSIF-M | C21: Consolidated sedimentary intergranular/fracture aquifer | E21: Medium productivity | F21: 3
A22: *CSIF-L | C22: Consolidated sedimentary intergranular/fracture aquifer | E22: Low productivity | F22: 1
A23: *These variables represents broad regional groundwater potential rather than local groundwater availability.
A26: Field | B26: Meaning
A27: Agricultural potential | B27: Interpretive recoding for modelling purposes only
A28: Potential score | B28: Ordinal support score (4 = highest, 1 = lowest)
A29: Note | B29: Scores combine soil/landform meaning in a simplified way and should be read together with hydrology.
A31: Source workbook fields used
A32: CLAF_FAO | B32: Dominant soil code | C32: SOTER_Terr | D32: Landform code

Sheet Chebba sites
A1: ID | B1: X (32S WGS84) | C1: Y (32S WGS84) | D1: Name | E1: Settlement category based on survey | F1: River_dist | G1: Road_dist | H1: Near_500 | I1: Near_750 | J1: Near_1000 | K1: Near_3000 | L1: SOTER_Terr | M1: Landform_name | N1: Landform_agri_potential | O1: Landform_agri_score | P1: Lithology | Q1: CLAF_FAO | R1: Soil_name | S1: Soil_group | T1: Soil_limitation | U1: Soil_agri_potential | V1: Soil_agri_score | W1: TunGLG | X1: TunHGComb | Y1: Aquifer producitivity | Z1: Archaeology
A2: AAT 1 | B2: 673557 | C2: 3912078 | D2: N/D | E2: N/D | F2: 547.63027 | G2: 1049.81 | H2: 348.24999 | I2: 348.24998 | J2: 348.24999 | K2: 547.63027 | L2: LP | M2: Plain | N2: Moderate-high | O2: 3 | P2: SO1 | Q2: CLp | R2: =VLOOKUP($S2,Legend!$A$12:$F$19,2,FALSE) -> Petric Calcisols | S2: =VLOOKUP($S2,Legend!$A$12:$F$19,3,FALSE) -> Calcisol | T2: =VLOOKUP($T2,Legend!$A$12:$F$19,4,FALSE) -> Petrocalcic hardpan / restricted rooting | U2: =VLOOKUP($S2,Legend!$A$12:$F$19,5,FALSE) -> Low | V2: 2 | W2: Unconsolidated | X2: U-H | Y2: 4
A3: AAT 2 | B3: 671700 | C3: 3911030 | D3: Henchir Ameur ben li | E3: N/D | F3: 251.18249 | G3: 2143.6746 | H3: 121.34625 | I3: 129.97035 | J3: 251.18249 | K3: 251.18249 | L3: LP | M3: Plain | N3: Moderate-high | O3: 3 | P3: SO1 | Q3: CLp | R3: =VLOOKUP($S3,Legend!$A$12:$F$19,2,FALSE) -> Petric Calcisols | S3: =VLOOKUP($S3,Legend!$A$12:$F$19,3,FALSE) -> Calcisol | T3: =VLOOKUP($T3,Legend!$A$12:$F$19,4,FALSE) -> Petrocalcic hardpan / restricted rooting | U3: =VLOOKUP($T3,Legend!$A$12:$F$19,5,FALSE) -> Low | V3: 2 | W3: Unconsolidated | X3: U-H | Y3: 4
A4: AAT 3 | B4: 671818 | C4: 3909099 | D4: Henchir Chkemania | E4: Small rural settlement? | F4: 1142.6098 | G4: 795.05953 | H4: 201.27641 | I4: 555.12078 | J4: 774.41276 | K4: 1142.6098 | L4: LP | M4: Plain | N4: Moderate-high | O4: 3 | P4: SO1 | Q4: CLp | R4: =VLOOKUP($S4,Legend!$A$12:$F$19,2,FALSE) -> Petric Calcisols | S4: =VLOOKUP($S4,Legend!$A$12:$F$19,3,FALSE) -> Calcisol | T4: =VLOOKUP($T4,Legend!$A$12:$F$19,4,FALSE) -> Petrocalcic hardpan / restricted rooting | U4: =VLOOKUP($T4,Legend!$A$12:$F$19,5,FALSE) -> Low | V4: 2 | W4: Unconsolidated | X4: U-H | Y4: 4
A5: AAT 4 | B5: 671991 | C5: 3907999 | D5: Henchir Chammar | E5: Small rural settlement? | F5: 72.56211 | G5: 115.0624 | H5: 71.7573 | I5: 71.7573 | J5: 71.7573 | K5: 72.56211 | L5: LP | M5: Plain | N5: Moderate-high | O5: 3 | P5: SO2 | Q5: CLp | R5: =VLOOKUP($S5,Legend!$A$12:$F$19,2,FALSE) -> Petric Calcisols | S5: =VLOOKUP($S5,Legend!$A$12:$F$19,3,FALSE) -> Calcisol | T5: =VLOOKUP($T5,Legend!$A$12:$F$19,4,FALSE) -> Petrocalcic hardpan / restricted rooting | U5: =VLOOKUP($T5,Legend!$A$12:$F$19,5,FALSE) -> Low | V5: 2 | W5: Unconsolidated | X5: U-H | Y5: 4
A6: AAT 5 | B6: 671599 | C6: 3906697 | D6: Henchir Chmamir | E6: N/D | F6: 207.21729 | G6: 82.874364 | H6: 207.21729 | I6: 207.21732 | J6: 207.21729 | K6: 207.21729 | L6: LP | M6: Plain | N6: Moderate-high | O6: 3 | P6: SO2 | Q6: CLp | R6: =VLOOKUP($S6,Legend!$A$12:$F$19,2,FALSE) -> Petric Calcisols | S6: =VLOOKUP($S6,Legend!$A$12:$F$19,3,FALSE) -> Calcisol | T6: =VLOOKUP($T6,Legend!$A$12:$F$19,4,FALSE) -> Petrocalcic hardpan / restricted rooting | U6: =VLOOKUP($T6,Legend!$A$12:$F$19,5,FALSE) -> Low | V6: 2 | W6: Unconsolidated | X6: U-H | Y6: 4
A7: AAT 6 | B7: 670861 | C7: 3905556 | D7: hercher el Kelba | E7: N/D | F7: 489.86988 | G7: 75.730214 | H7: 489.86988 | I7: 489.86991 | J7: 489.86988 | K7: 489.86988 | L7: LP | M7: Plain | N7: Moderate-high | O7: 3 | P7: SO2 | Q7: CLp | R7: =VLOOKUP($S7,Legend!$A$12:$F$19,2,FALSE) -> Petric Calcisols | S7: =VLOOKUP($S7,Legend!$A$12:$F$19,3,FALSE) -> Calcisol | T7: =VLOOKUP($T7,Legend!$A$12:$F$19,4,FALSE) -> Petrocalcic hardpan / restricted rooting | U7: =VLOOKUP($T7,Legend!$A$12:$F$19,5,FALSE) -> Low | V7: 2 | W7: Unconsolidated | X7: U-H | Y7: 4
A8: AAT 7 | B8: 672158 | C8: 3905111 | D8: N/D | E8: N/D | F8: 515.02768 | G8: 1423.0462 | H8: 231.40458 | I8: 225.76708 | J8: 506.62243 | K8: 515.02768 | L8: LP | M8: Plain | N8: Moderate-high | O8: 3 | P8: SO2 | Q8: CLp | R8: =VLOOKUP($S8,Legend!$A$12:$F$19,2,FALSE) -> Petric Calcisols | S8: =VLOOKUP($S8,Legend!$A$12:$F$19,3,FALSE) -> Calcisol | T8: =VLOOKUP($T8,Legend!$A$12:$F$19,4,FALSE) -> Petrocalcic hardpan / restricted rooting | U8: =VLOOKUP($T8,Legend!$A$12:$F$19,5,FALSE) -> Low | V8: 2 | W8: Unconsolidated | X8: U-H | Y8: 4
A9: AAT 8 | B9: 672714 | C9: 3905546 | D9: henchir Britset | E9: N/D | F9: 133.89922 | G9: 1607.3478 | H9: 133.89922 | I9: 133.89921 | J9: 133.89922 | K9: 133.89922 | L9: LP | M9: Plain | N9: Moderate-high | O9: 3 | P9: SO2 | Q9: CLp | R9: =VLOOKUP($S9,Legend!$A$12:$F$19,2,FALSE) -> Petric Calcisols | S9: =VLOOKUP($S9,Legend!$A$12:$F$19,3,FALSE) -> Calcisol | T9: =VLOOKUP($T9,Legend!$A$12:$F$19,4,FALSE) -> Petrocalcic hardpan / restricted rooting | U9: =VLOOKUP($T9,Legend!$A$12:$F$19,5,FALSE) -> Low | V9: 2 | W9: Unconsolidated | X9: U-H | Y9: 4
A10: AAT 9 | B10: 675371 | C10: 3904906 | D10: Henchir Fnien | E10: N/D | F10: 54.54092 | G10: 4243.78 | H10: 54.54092 | I10: 54.5409 | J10: 54.54092 | K10: 54.54092 | L10: LP | M10: Plain | N10: Moderate-high | O10: 3 | P10: SO1 | Q10: CLp | R10: =VLOOKUP($S10,Legend!$A$12:$F$19,2,FALSE) -> Petric Calcisols | S10: =VLOOKUP($S10,Legend!$A$12:$F$19,3,FALSE) -> Calcisol | T10: =VLOOKUP($T10,Legend!$A$12:$F$19,4,FALSE) -> Petrocalcic hardpan / restricted rooting | U10: =VLOOKUP($T10,Legend!$A$12:$F$19,5,FALSE) -> Low | V10: 2 | W10: Cretaceous-Tertiary sedimentary | X10: CSIF-M | Y10: 3
A11: AAT 10 | B11: 674256 | C11: 3906143 | D11: Henchir Zerda | E11: N/D | F11: 1012.3614 | G11: 2667.5741 | H11: 7.219228 | I11: 7.219228 | J11: 7.219228 | K11: 1012.3614 | L11: LP | M11: Plain | N11: Moderate-high | O11: 3 | P11: SO2 | Q11: CLp | R11: =VLOOKUP($S11,Legend!$A$12:$F$19,2,FALSE) -> Petric Calcisols | S11: =VLOOKUP($S11,Legend!$A$12:$F$19,3,FALSE) -> Calcisol | T11: =VLOOKUP($T11,Legend!$A$12:$F$19,4,FALSE) -> Petrocalcic hardpan / restricted rooting | U11: =VLOOKUP($T11,Legend!$A$12:$F$19,5,FALSE) -> Low | V11: 2 | W11: Cretaceous-Tertiary sedimentary | X11: CSIF-M | Y11: 3
A12: AAT 11 | B12: 674496 | C12: 3908159 | D12: henchir el Assed | E12: N/D | F12: 122.27161 | G12: 1787.1742 | H12: 122.27161 | I12: 122.27161 | J12: 122.27161 | K12: 122.27161 | L12: LP | M12: Plain | N12: Moderate-high | O12: 3 | P12: SO2 | Q12: CLp | R12: =VLOOKUP($S12,Legend!$A$12:$F$19,2,FALSE) -> Petric Calcisols | S12: =VLOOKUP($S12,Legend!$A$12:$F$19,3,FALSE) -> Calcisol | T12: =VLOOKUP($T12,Legend!$A$12:$F$19,4,FALSE) -> Petrocalcic hardpan / restricted rooting | U12: =VLOOKUP($T12,Legend!$A$12:$F$19,5,FALSE) -> Low | V12: 2 | W12: Unconsolidated | X12: U-H | Y12: 4
A13: AAT 12 | B13: 673456 | C13: 3908909 | D13: Henchir el Hauta | E13: N/D | F13: 989.83632 | G13: 505.00323 | H13: 259.62869 | I13: 259.64026 | J13: 355.44146 | K13: 989.83632 | L13: LP | M13: Plain | N13: Moderate-high | O13: 3 | P13: SO1 | Q13: CLp | R13: =VLOOKUP($S13,Legend!$A$12:$F$19,2,FALSE) -> Petric Calcisols | S13: =VLOOKUP($S13,Legend!$A$12:$F$19,3,FALSE) -> Calcisol | T13: =VLOOKUP($T13,Legend!$A$12:$F$19,4,FALSE) -> Petrocalcic hardpan / restricted rooting | U13: =VLOOKUP($T13,Legend!$A$12:$F$19,5,FALSE) -> Low | V13: 2 | W13: Unconsolidated | X13: U-H | Y13: 4
A14: AAT 13 | B14: 674155 | C14: 3909912 | D14: N/D | E14: Insufficient data | F14: 616.61077 | G14: 535.02378 | H14: 589.3822 | I14: 616.61081 | J14: 616.61077 | K14: 616.61077 | L14: LP | M14: Plain | N14: Moderate-high | O14: 3 | P14: SO1 | Q14: CLp | R14: =VLOOKUP($S14,Legend!$A$12:$F$19,2,FALSE) -> Petric Calcisols | S14: =VLOOKUP($S14,Legend!$A$12:$F$19,3,FALSE) -> Calcisol | T14: =VLOOKUP($T14,Legend!$A$12:$F$19,4,FALSE) -> Petrocalcic hardpan / restricted rooting | U14: =VLOOKUP($T14,Legend!$A$12:$F$19,5,FALSE) -> Low | V14: 2 | W14: Unconsolidated | X14: U-H | Y14: 4
... A18: AAT 17 | B18: 677105 | C18: 3910330 | D18: Henchir Terchga | E18: Villa? | F18: 187.95243 | G18: 2632.3919 | H18: 187.95243 | I18: 187.95241 | J18: 187.95243 | K18: 187.95243 | L18: LP | M18: Plain | N18: Moderate-high | O18: 3 | P18: SO2 | Q18: CLp | R18: =VLOOKUP($S18,Legend!$A$12:$F$19,2,FALSE) -> Petric Calcisols | S18: =VLOOKUP($S18,Legend!$A$12:$F$19,3,FALSE) -> Calcisol | T18: =VLOOKUP($T18,Legend!$A$12:$F$19,4,FALSE) -> Petrocalcic hardpan / restricted rooting | U18: =VLOOKUP($T18,Legend!$A$12:$F$19,5,FALSE) -> Low | V18: 2 | W18: Unconsolidated | X18: U-H | Y18: 4
A19: AAT 18 | B19: 678188 | C19: 3908273 | D19: henchir Mbdas Zabb | E19: N/D | F19: 858.28646 | G19: 4878.9012 | H19: 247.32686 | I19: 247.3269 | J19: 247.32686 | K19: 858.28646 | L19: LP | M19: Plain | N19: Moderate-high | O19: 3 | P19: UF | Q19: FLe | R19: =VLOOKUP($T19,Legend!$A$12:$F$19,2,FALSE) -> Eutric Fluvisols | S19: =VLOOKUP($T19,Legend!$A$12:$F$19,3,FALSE) -> Fluvisol | T19: =VLOOKUP($T19,Legend!$A$12:$F$19,4,FALSE) -> Alluvial soil; generally fertile | U19: High | V19: 4 | W19: Unconsolidated | X19: U-H | Y19: 4
A20: AAT 19 | B20: 676926 | C20: 3907006 | D20: Henchir Mna | E20: N/D | F20: 434.10537 | G20: 4427.9957 | H20: 24.224267 | I20: 24.224253 | J20: 112.28706 | K20: 434.10537 | L20: LP | M20: Plain | N20: Moderate-high | O20: 3 | P20: SO2 | Q20: CLp | R20: =VLOOKUP($S20,Legend!$A$12:$F$19,2,FALSE) -> Petric Calcisols | S20: =VLOOKUP($S20,Legend!$A$12:$F$19,3,FALSE) -> Calcisol | T20: =VLOOKUP($T20,Legend!$A$12:$F$19,4,FALSE) -> Petrocalcic hardpan / restricted rooting | U20: Low | V20: 2 | W20: Cretaceous-Tertiary sedimentary | X20: CSIF-M | Y20: 3
A21: AAT 20 | B21: 677896 | C21: 3905538 | D21: Henchir Zriq | E21: Small rural settlement? | F21: 109.52525 | G21: 6079.0342 | H21: 109.52525 | I21: 109.5253 | J21: 109.52525 | K21: 109.52525 | L21: LP | M21: Plain | N21: Moderate-high | O21: 3 | P21: SO1 | Q21: CLp | R21: =VLOOKUP($S21,Legend!$A$12:$F$19,2,FALSE) -> Petric Calcisols | S21: =VLOOKUP($S21,Legend!$A$12:$F$19,3,FALSE) -> Calcisol | T21: =VLOOKUP($T21,Legend!$A$12:$F$19,4,FALSE) -> Petrocalcic hardpan / restricted rooting | U21: =VLOOKUP($T21,Legend!$A$12:$F$19,5,FALSE) -> Low | V21: 2 | W21: Cretaceous-Tertiary sedimentary | X21: CSIF-M | Y21: 3
A22: AAT 21 | B22: 678152 | C22: 3904749 | D22: Henchir Taumania | E22: Small rural settlement? | F22: 136.43447 | G22: 6761.728 | H22: 135.32925 | I22: 135.32923 | J22: 136.43447 | K22: 136.43447 | L22: LP | M22: Plain | N22: Moderate-high | O22: 3 | P22: SO1 | Q22: CLp | R22: =VLOOKUP($S22,Legend!$A$12:$F$19,2,FALSE) -> Petric Calcisols | S22: =VLOOKUP($S22,Legend!$A$12:$F$19,3,FALSE) -> Calcisol | T22: =VLOOKUP($T22,Legend!$A$12:$F$19,4,FALSE) -> Petrocalcic hardpan / restricted rooting | U22: =VLOOKUP($T22,Legend!$A$12:$F$19,5,FALSE) -> Low | V22: 2 | W22: Cretaceous-Tertiary sedimentary | X22: CSIF-M | Y22: 3
A23: AAT 22 | B23: 680243 | C23: 3904463 | D23: Henchir el Massaua | E23: N/D | F23: 26.530752 | G23: 6263.1737 | H23: 29.428221 | I23: 29.428212 | J23: 26.530752 | K23: 26.530752 | L23: LP | M23: Plain | N23: Moderate-high | O23: 3 | P23: SO1 | Q23: CLp | R23: =VLOOKUP($S23,Legend!$A$12:$F$19,2,FALSE) -> Petric Calcisols | S23: =VLOOKUP($S23,Legend!$A$12:$F$19,3,FALSE) -> Calcisol | T23: =VLOOKUP($T23,Legend!$A$12:$F$19,4,FALSE) -> Petrocalcic hardpan / restricted rooting | U23: =VLOOKUP($T23,Legend!$A$12:$F$19,5,FALSE) -> Low | V23: 2 | W23: Cretaceous-Tertiary sedimentary | X23: CSIF-M | Y23: 3
A24: AAT 23 | B24: 678950 | C24: 3905598 | D24: Henchir Rarbet er Ra | E24: N/D | F24: 809.6976 | G24: 6893.1364 | H24: 325.25767 | I24: 703.72128 | J24: 809.6976 | K24: 809.6976 | L24: LP | M24: Plain | N24: Moderate-high | O24: 3 | P24: SO1 | Q24: CLp | R24: =VLOOKUP($S24,Legend!$A$12:$F$19,2,FALSE) -> Petric Calcisols | S24: =VLOOKUP($S24,Legend!$A$12:$F$19,3,FALSE) -> Calcisol | T24: =VLOOKUP($T24,Legend!$A$12:$F$19,4,FALSE) -> Petrocalcic hardpan / restricted rooting | U24: =VLOOKUP($T24,Legend!$A$12:$F$19,5,FALSE) -> Low | V24: 2 | W24: Cretaceous-Tertiary sedimentary | X24: CSIF-M | Y24: 3
A25: AAT 24 | B25: 681269 | C25: 3906610 | D25: Henchir bel Hetuie | E25: N/D | F25: 4.126847 | G25: 4854.9739 | H25: 15.566309 | I25: 15.566333 | J25: 15.566309 | K25: 4.126847 | L25: LP | M25: Plain | N25: Moderate-high | O25: 3 | P25: SO1 | Q25: CLp | R25: =VLOOKUP($S25,Legend!$A$12:$F$19,2,FALSE) -> Petric Calcisols | S25: =VLOOKUP($S25,Legend!$A$12:$F$19,3,FALSE) -> Calcisol | T25: =VLOOKUP($T25,Legend!$A$12:$F$19,4,FALSE) -> Petrocalcic hardpan / restricted rooting | U25: =VLOOKUP($T25,Legend!$A$12:$F$19,5,FALSE) -> Low | V25: 2 | W25: Cretaceous-Tertiary sedimentary | X25: CSIF-M | Y25: 3
A26: AAT 25 | B26: 680882 | C26: 3907666 | D26: Henchir el Kasouir | E26: N/D | F26: 383.26549 | G26: 4845.7575 | H26: 335.61939 | I26: 383.26551 | J26: 383.26549 | K26: 383.26549 | L26: LP | M26: Plain | N26: Moderate-high | O26: 3 | P26: UF | Q26: FLe | R26: =VLOOKUP($T26,Legend!$A$12:$F$19,2,FALSE) -> Eutric Fluvisols | S26: =VLOOKUP($T26,Legend!$A$12:$F$19,3,FALSE) -> Fluvisol | T26: =VLOOKUP($T26,Legend!$A$12:$F$19,4,FALSE) -> Alluvial soil; generally fertile | U26: High | V26: 4 | W26: Cretaceous-Tertiary sedimentary | X26: CSIF-M | Y26: 3
A27: AAT 26 | B27: 679303 | C27: 3911494 | D27: Henchir Sauauli Krish | E27: N/D | F27: 926.67772 | G27: 3595.776 | H27: 224.10223 | I27: 224.10226 | J27: 224.10223 | K27: 926.67772 | L27: LP | M27: Plain | N27: Moderate-high | O27: 3 | P27: UF | Q27: FLe | R27: =VLOOKUP($T27,Legend!$A$12:$F$19,2,FALSE) -> Eutric Fluvisols | S27: =VLOOKUP($T27,Legend!$A$12:$F$19,3,FALSE) -> Fluvisol | T27: =VLOOKUP($T27,Legend!$A$12:$F$19,4,FALSE) -> Alluvial soil; generally fertile | U27: High | V27: 4 | W27: Unconsolidated | X27: U-H | Y27: 4
A28: AAT 27 | B28: 682499 | C28: 3910722 | D28: N/D | E28: N/D | F28: 388.86783 | G28: 2361.0583 | H28: 124.46499 | I28: 124.465 | J28: 280.30684 | K28: 388.86783 | L28: LP | M28: Plain | N28: Moderate-high | O28: 3 | P28: UF | Q28: FLe | R28: =VLOOKUP($T28,Legend!$A$12:$F$19,2,FALSE) -> Eutric Fluvisols | S28: =VLOOKUP($T28,Legend!$A$12:$F$19,3,FALSE) -> Fluvisol | T28: =VLOOKUP($T28,Legend!$A$12:$F$19,4,FALSE) -> Alluvial soil; generally fertile | U28: High | V28: 4 | W28: Unconsolidated | X28: U-H | Y28: 4
A29: AAT 28 | B29: 681692 | C29: 3909689 | D29: Henchir Zeroua | E29: Probable villa | F29: 193.14151 | G29: 3463.6958 | H29: 147.48319 | I29: 193.14156 | J29: 193.14151 | K29: 193.14151 | L29: LP | M29: Plain | N29: Moderate-high | O29: 3 | P29: UF | Q29: FLe | R29: =VLOOKUP($T29,Legend!$A$12:$F$19,2,FALSE) -> Eutric Fluvisols | S29: =VLOOKUP($T29,Legend!$A$12:$F$19,3,FALSE) -> Fluvisol | T29: =VLOOKUP($T29,Legend!$A$12:$F$19,4,FALSE) -> Alluvial soil; generally fertile | U29: High | V29: 4 | W29: Unconsolidated | X29: U-H | Y29: 4
A30: AAT 29 | B30: 682690 | C30: 3908499 | D30: henchir Adna | E30: N/D | F30: 117.39248 | G30: 2869.4341 | H30: 117.39248 | I30: 117.39251 | J30: 117.39248 | K30: 117.39248 | L30: LP | M30: Plain | N30: Moderate-high | O30: 3 | P30: SO1 | Q30: CLp | R30: =VLOOKUP($S30,Legend!$A$12:$F$19,2,FALSE) -> Petric Calcisols | S30: =VLOOKUP($S30,Legend!$A$12:$F$19,3,FALSE) -> Calcisol | T30: =VLOOKUP($T30,Legend!$A$12:$F$19,4,FALSE) -> Petrocalcic hardpan / restricted rooting | U30: =VLOOKUP($T30,Legend!$A$12:$F$19,5,FALSE) -> Low | V30: 2 | W30: Cretaceous-Tertiary sedimentary | X30: CSIF-M | Y30: 3
A31: AAT 30 | B31: 686298 | C31: 3909225 | D31: N/D | E31: Rural settlement. Farm? | F31: 876.15779 | G31: 743.51969 | H31: 876.15779 | I31: 876.15776 | J31: 876.15779 | K31: 876.15779 | L31: LP | M31: Plain | N31: Moderate-high | O31: 3 | P31: UE | Q31: ARh | R31: Eolian | S31: Haplic Arenosol | T31: sandy / low water retention | U31: Low | V31: 2 | W31: Unconsolidated | X31: U-H | Y31: 4
A32: AAT 31 | B32: 684533 | C32: 3907350 | D32: Henchir Zlassi | E32: Rural settlement (indeterminate typology) | F32: 115.87163 | G32: 1558.6938 | H32: 115.87163 | I32: 115.8716 | J32: 115.87163 | K32: 115.87163 | L32: LP | M32: Plain | N32: Moderate-high | O32: 3 | P32: SO1 | Q32: CLp | R32: =VLOOKUP($S32,Legend!$A$12:$F$19,2,FALSE) -> Petric Calcisols | S32: =VLOOKUP($S32,Legend!$A$12:$F$19,3,FALSE) -> Calcisol | T32: =VLOOKUP($T32,Legend!$A$12:$F$19,4,FALSE) -> Petrocalcic hardpan / restricted rooting | U32: =VLOOKUP($T32,Legend!$A$12:$F$19,5,FALSE) -> Low | V32: 2 | W32: Unconsolidated | X32: U-H | Y32: 4
A33: AAT 32 | B33: 685442 | C33: 3907151 | D33: Henchir el Mrair | E33: N/D | F33: 309.78693 | G33: 660.5119 | H33: 228.6487 | I33: 228.64865 | J33: 228.6487 | K33: 309.78693 | L33: LP | M33: Plain | N33: Moderate-high | O33: 3 | P33: SO1 | Q33: CLp | R33: =VLOOKUP($S33,Legend!$A$12:$F$19,2,FALSE) -> Petric Calcisols | S33: =VLOOKUP($S33,Legend!$A$12:$F$19,3,FALSE) -> Calcisol | T33: =VLOOKUP($T33,Legend!$A$12:$F$19,4,FALSE) -> Petrocalcic hardpan / restricted rooting | U33: =VLOOKUP($T33,Legend!$A$12:$F$19,5,FALSE) -> Low | V33: 2 | W33: Unconsolidated | X33: U-H | Y33: 4
A34: AAT 33 | B34: 687998 | C34: 3907633 | D34: El Areg | E34: Villa? | F34: 897.88304 | G34: 1915.9994 | H34: 735.12211 | I34: 728.62313 | J34: 888.87905 | K34: 897.88304 | L34: LP | M34: Plain | N34: Moderate-high | O34: 3 | P34: UE | Q34: ARh | R34: Eolian | S34: Haplic Arenosol | T34: sandy / low water retention | U34: Low | V34: 2 | W34: Unconsolidated | X34: U-H | Y34: 4
A35: AAT 34 | B35: 686097 | C35: 3906587 | D35: Henchir el Kedelet | E35: N/D | F35: 931.31034 | G35: 35.773287 | H35: 167.97096 | I35: 167.97098 | J35: 167.97096 | K35: 931.31034 | L35: LP | M35: Plain | N35: Moderate-high | O35: 3 | P35: SO1 | Q35: CLp | R35: =VLOOKUP($S35,Legend!$A$12:$F$19,2,FALSE) -> Petric Calcisols | S35: =VLOOKUP($S35,Legend!$A$12:$F$19,3,FALSE) -> Calcisol | T35: =VLOOKUP($T35,Legend!$A$12:$F$19,4,FALSE) -> Petrocalcic hardpan / restricted rooting | U35: =VLOOKUP($T35,Legend!$A$12:$F$19,5,FALSE) -> Low | V35: 2 | W35: Unconsolidated | X35: U-H | Y35: 4
A36: AAT 35 | B36: 685472 | C36: 3905724 | D36: N/D | E36: N/D | F36: 945.56976 | G36: 976.67832 | H36: 284.03039 | I36: 284.6844 | J36: 284.68438 | K36: 945.56976 | L36: LP | M36: Plain | N36: Moderate-high | O36: 3 | P36: SO1 | Q36: CLp | R36: =VLOOKUP($S36,Legend!$A$12:$F$19,2,FALSE) -> Petric Calcisols | S36: =VLOOKUP($S36,Legend!$A$12:$F$19,3,FALSE) -> Calcisol | T36: =VLOOKUP($T36,Legend!$A$12:$F$19,4,FALSE) -> Petrocalcic hardpan / restricted rooting | U36: =VLOOKUP($T36,Legend!$A$12:$F$19,5,FALSE) -> Low | V36: 2 | W36: Cretaceous-Tertiary sedimentary | X36: CSIF-M | Y36: 3
A37: AAT 36 | B37: 687168 | C37: 3905462 | D37: N/D | E37: N/D | F37: 494.305 | G37: 73.211272 | H37: 416.2486 | I37: 416.24859 | J37: 416.2486 | K37: 494.305 | L37: LP | M37: Plain | N37: Moderate-high | O37: 3 | P37: SO1 | Q37: CLp | R37: =VLOOKUP($S37,Legend!$A$12:$F$19,2,FALSE) -> Petric Calcisols | S37: =VLOOKUP($S37,Legend!$A$12:$F$19,3,FALSE) -> Calcisol | T37: =VLOOKUP($T37,Legend!$A$12:$F$19,4,FALSE) -> Petrocalcic hardpan / restricted rooting | U37: =VLOOKUP($T37,Legend!$A$12:$F$19,5,FALSE) -> Low | V37: 2 | W37: Unconsolidated | X37: U-H | Y37: 4
A38: AAT 37 | B38: 687744 | C38: 3905102 | D38: Henchir Djefla | E38: Small rural settlement? | F38: 613.19806 | G38: 235.50674 | H38: 91.512657 | I38: 91.512662 | J38: 91.512657 | K38: 613.19806 | L38: LP | M38: Plain | N38: Moderate-high | O38: 3 | P38: SO1 | Q38: CLp | R38: =VLOOKUP($S38,Legend!$A$12:$F$19,2,FALSE) -> Petric Calcisols | S38: =VLOOKUP($S38,Legend!$A$12:$F$19,3,FALSE) -> Calcisol | T38: =VLOOKUP($T38,Legend!$A$12:$F$19,4,FALSE) -> Petrocalcic hardpan / restricted rooting | U38: =VLOOKUP($T38,Legend!$A$12:$F$19,5,FALSE) -> Low | V38: 2 | W38: Unconsolidated | X38: U-H | Y38: 4
A39: AAT 38 | B39: 686473 | C39: 3905027 | D39: Henchir Djebenine | E39: Probable villa | F39: 1293.316 | G39: 651.37965 | H39: 492.27092 | I39: 802.29431 | J39: 1067.6606 | K39: 1293.316 | L39: LP | M39: Plain | N39: Moderate-high | O39: 3 | P39: SO1 | Q39: CLp | R39: =VLOOKUP($S39,Legend!$A$12:$F$19,2,FALSE) -> Petric Calcisols | S39: =VLOOKUP($S39,Legend!$A$12:$F$19,3,FALSE) -> Calcisol | T39: =VLOOKUP($T39,Legend!$A$12:$F$19,4,FALSE) -> Petrocalcic hardpan / restricted rooting | U39: =VLOOKUP($T39,Legend!$A$12:$F$19,5,FALSE) -> Low | V39: 2 | W39: Unconsolidated | X39: U-H | Y39: 4
A40: AAT 39 | B40: 687450 | C40: 3903958 | D40: Close to Henchir Djefla | E40: N/D | F40: 1672.872 | G40: 1160.8216 | H40: 880.93903 | I40: 880.939 | J40: 909.82031 | K40: 1672.872 | L40: LP | M40: Plain | N40: Moderate-high | O40: 3 | P40: SO1 | Q40: CLp | R40: =VLOOKUP($S40,Legend!$A$12:$F$19,2,FALSE) -> Petric Calcisols | S40: =VLOOKUP($S40,Legend!$A$12:$F$19,3,FALSE) -> Calcisol | T40: =VLOOKUP($T40,Legend!$A$12:$F$19,4,FALSE) -> Petrocalcic hardpan / restricted rooting | U40: =VLOOKUP($T40,Legend!$A$12:$F$19,5,FALSE) -> Low | V40: 2 | W40: Unconsolidated | X40: U-H | Y40: 4
A41: AAT 40 | B41: 689650 | C41: 3902437 | D41: N/D | E41: N/D | F41: 441.9094 | G41: 57.573788 | H41: 348.71335 | I41: 353.08511 | J41: 353.08509 | K41: 441.9094 | L41: LP | M41: Plain | N41: Moderate-high | O41: 3 | P41: SO1 | Q41: CLp | R41: =VLOOKUP($S41,Legend!$A$12:$F$19,2,FALSE) -> Petric Calcisols | S41: =VLOOKUP($S41,Legend!$A$12:$F$19,3,FALSE) -> Calcisol | T41: =VLOOKUP($T41,Legend!$A$12:$F$19,4,FALSE) -> Petrocalcic hardpan / restricted rooting | U41: =VLOOKUP($T41,Legend!$A$12:$F$19,5,FALSE) -> Low | V41: 2 | W41: Unconsolidated | X41: U-H | Y41: 4
A42: AAT 41 | B42: 693174 | C42: 3902901 | D42: Sidi Abdullah | E42: Small rural settlement? | F42: 2066.4997 | G42: 1855.1442 | H42: 660.60517 | I42: 679.73631 | J42: 715.16238 | K42: 2066.4997 | L42: LP | M42: Plain | N42: Moderate-high | O42: 3 | P42: SO1 | Q42: CLp | R42: =VLOOKUP($S42,Legend!$A$12:$F$19,2,FALSE) -> Petric Calcisols | S42: =VLOOKUP($S42,Legend!$A$12:$F$19,3,FALSE) -> Calcisol | T42: =VLOOKUP($T42,Legend!$A$12:$F$19,4,FALSE) -> Petrocalcic hardpan / restricted rooting | U42: =VLOOKUP($T42,Legend!$A$12:$F$19,5,FALSE) -> Low | V42: 2 | W42: Unconsolidated | X42: U-H | Y42: 4
A43: AAT 43 | B43: 692634 | C43: 3902357 | D43: N/D | E43: N/D | F43: 1326.7564 | G43: 1122.6728 | H43: 53.095205 | I43: 178.27799 | J43: 332.59608 | K43: 1326.7564 | L43: LP | M43: Plain | N43: Moderate-high | O43: 3 | P43: SO1 | Q43: CLp | R43: =VLOOKUP($S43,Legend!$A$12:$F$19,2,FALSE) -> Petric Calcisols | S43: =VLOOKUP($S43,Legend!$A$12:$F$19,3,FALSE) -> Calcisol | T43: =VLOOKUP($T43,Legend!$A$12:$F$19,4,FALSE) -> Petrocalcic hardpan / restricted rooting | U43: =VLOOKUP($T43,Legend!$A$12:$F$19,5,FALSE) -> Low | V43: 2 | W43: Unconsolidated | X43: U-H | Y43: 4
...

Sheet Other sites
A1: FID | B1: Site | C1: Name | D1: X__32S_WGS | E1: Y__32S_WGS | F1: Surface__h | G1: Type | H1: Level_of_c | I1: River_dist | J1: Road_dist | K1: Near_500 | L1: Near_750 | M1: Near_1000 | N1: Near_3000 | O1: SOTER_Terr | P1: Landform_name | Q1: Landform_agri_potential | R1: Landform_agri_score | S1: Lithology | T1: CLAF_FAO | U1: Soil_name | V1: Soil_group | W1: Soil_limitation | X1: Soil_agri_potential | Y1: Soil_agri_score | Z1: TunGLG | AA1: TunHGComb | AB1: Aquifer producitivity | AC1: Archaeology
A2: 0 | B2: 43.013 | C2: Henchir al Kbir / Henchir el Hfayir | D2: 632521.65 | E2: 4012584.7 | F2: 12.669 | G2: villa | H2: medium | I2: 2141.0475 | J2: 268.43102 | K2: 67.590149 | L2: 67.5901 | M2: 67.590149 | N2: 67.590149 | O2: LP | P2: =VLOOKUP($O2,Legend!$H$12:$K$15,2,FALSE) -> Plain | Q2: =VLOOKUP($O2,Legend!$H$12:$K$15,3,FALSE) -> Moderate-high | R2: =VLOOKUP($O2,Legend!$H$12:$K$15,4,FALSE) -> 3 | S2: UM | T2: SCn | U2: =VLOOKUP($T2,Legend!$A$12:$F$19,2,FALSE) -> Sodic Solonchaks | V2: =VLOOKUP($T2,Legend!$A$12:$F$19,3,FALSE) -> Solonchak | W2: =VLOOKUP($T2,Legend!$A$12:$F$19,4,FALSE) -> Salinity and sodicity | X2: =VLOOKUP($T2,Legend!$A$12:$F$19,5,FALSE) -> Very low | Y2: =VLOOKUP($T2,Legend!$A$12:$F$19,6,FALSE) -> 1 | Z2: Unconsolidated | AA2: U-H | AB2: 4 | AC2: Construcciones, enduit étanche, mármol, teselas, tubos, necrópolis
A3: 1 | B3: 43.029 | C3: Sans nom | D3: 626552 | E3: 4008251 | F3: 8.5 | G3: villa | H3: medium | I3: 45.173474 | J3: 1111.0078 | K3: 82.902255 | L3: 82.9023 | M3: 82.902255 | N3: 222.71787 | O3: LV | P3: =VLOOKUP($O3,Legend!$H$12:$K$15,2,FALSE) -> Valley floor | Q3: =VLOOKUP($O3,Legend!$H$12:$K$15,3,FALSE) -> High | R3: =VLOOKUP($O3,Legend!$H$12:$K$15,4,FALSE) -> 4 | S3: UF | T3: GLe | U3: =VLOOKUP($T3,Legend!$A$12:$F$19,2,FALSE) -> Eutric Gleysols | V3: =VLOOKUP($T3,Legend!$A$12:$F$19,3,FALSE) -> Gleysol | W3: =VLOOKUP($T3,Legend!$A$12:$F$19,4,FALSE) -> Poor drainage / waterlogging | X3: =VLOOKUP($T3,Legend!$A$12:$F$19,5,FALSE) -> Low | Y3: =VLOOKUP($T3,Legend!$A$12:$F$19,6,FALSE) -> 2 | Z3: Unconsolidated | AA3: U-H | AB3: 4 | AC3: Termas, dos cisternas, suelo con enduit étanche, grand appareil, opus figlinum, umbral, fuste
A4: 2 | B4: 43.034 | C4: Jbel Boughabhouba | D4: 627840.32 | E4: 4008905.8 | F4: 10.026 | G4: villa | H4: medium | I4: 472.52099 | J4: 218.56969 | K4: 222.69762 | L4: 222.69757 | M4: 222.69762 | N4: 229.34164 | O4: LV | P4: =VLOOKUP($O4,Legend!$H$12:$K$15,2,FALSE) -> Valley floor | Q4: =VLOOKUP($O4,Legend!$H$12:$K$15,3,FALSE) -> High | R4: =VLOOKUP($O4,Legend!$H$12:$K$15,4,FALSE) -> 4 | S4: UF | T4: GLe | U4: =VLOOKUP($T4,Legend!$A$12:$F$19,2,FALSE) -> Eutric Gleysols | V4: =VLOOKUP($T4,Legend!$A$12:$F$19,3,FALSE) -> Gleysol | W4: =VLOOKUP($T4,Legend!$A$12:$F$19,4,FALSE) -> Poor drainage / waterlogging | X4: =VLOOKUP($T4,Legend!$A$12:$F$19,5,FALSE) -> Low | Y4: =VLOOKUP($T4,Legend!$A$12:$F$19,6,FALSE) -> 2 | Z4: Unconsolidated | AA4: U-H | AB4: 4 | AC4: Construcciones probablemente termales, contrapeso, grand appareil, umbral, fuste, mosaico
A5: 3 | B5: 43.038 | C5: Sidi Saâda | D5: 629196.33 | E5: 4005951.1 | F5: 3.494 | G5: villa | H5: medium | I5: 506.85422 | J5: 1330.2847 | K5: 598.34596 | L5: 598.34596 | M5: 598.34596 | N5: 598.34596 | O5: LV | P5: =VLOOKUP($O5,Legend!$H$12:$K$15,2,FALSE) -> Valley floor | Q5: =VLOOKUP($O5,Legend!$H$12:$K$15,3,FALSE) -> High | R5: =VLOOKUP($O5,Legend!$H$12:$K$15,4,FALSE) -> 4 | S5: UF | T5: GLe | U5: =VLOOKUP($T5,Legend!$A$12:$F$19,2,FALSE) -> Eutric Gleysols | V5: =VLOOKUP($T5,Legend!$A$12:$F$19,3,FALSE) -> Gleysol | W5: =VLOOKUP($T5,Legend!$A$12:$F$19,4,FALSE) -> Poor drainage / waterlogging | X5: =VLOOKUP($T5,Legend!$A$12:$F$19,5,FALSE) -> Low | Y5: =VLOOKUP($T5,Legend!$A$12:$F$19,6,FALSE) -> 2 | Z5: Unconsolidated | AA5: U-H | AB5: 4 | AC5: Vestigios de termas, cisterna, edificio en opus africanum 12×8 m, mosaico, mármol, tubos
A6: 4 | B6: 43.137 | C6: Henchir l’Abbasi | D6: 621613.67 | E6: 3995908 | F6: 5.945 | G6: villa | H6: medium | I6: 208.06264 | J6: 762.96753 | K6: 98.567489 | L6: 98.5675 | M6: 98.567489 | N6: 98.567489 | O6: LP | P6: =VLOOKUP($O6,Legend!$H$12:$K$15,2,FALSE) -> Plain | Q6: =VLOOKUP($O6,Legend!$H$12:$K$15,3,FALSE) -> Moderate-high | R6: =VLOOKUP($O6,Legend!$H$12:$K$15,4,FALSE) -> 3 | S6: UM | T6: GLe | U6: =VLOOKUP($T6,Legend!$A$12:$F$19,2,FALSE) -> Eutric Gleysols | V6: =VLOOKUP($T6,Legend!$A$12:$F$19,3,FALSE) -> Gleysol | W6: =VLOOKUP($T6,Legend!$A$12:$F$19,4,FALSE) -> Poor drainage / waterlogging | X6: =VLOOKUP($T6,Legend!$A$12:$F$19,5,FALSE) -> Low | Y6: =VLOOKUP($T6,Legend!$A$12:$F$19,6,FALSE) -> 2 | Z6: Unconsolidated | AA6: U-H | AB6: 4 | AC6: Edificio en moellons, grand appareil disperso, mosaicos, mármol, ánforas; huilerie asociada
A7: 5 | B7: 43.179 | C7: Hecher: Sidi Bel | D7: 608393.04 | E7: 3999383.3 | F7: 5.578 | G7: villa | H7: medium | I7: 331.39018 | J7: 385.14148 | K7: 166.67337 | L7: 166.6734 | M7: 166.67337 | N7: 166.67337 | O7: LP | P7: =VLOOKUP($O7,Legend!$H$12:$K$15,2,FALSE) -> Plain | Q7: =VLOOKUP($O7,Legend!$H$12:$K$15,3,FALSE) -> Moderate-high | R7: =VLOOKUP($O7,Legend!$H$12:$K$15,4,FALSE) -> 3 | S7: SO1 | T7: CLh | U7: =VLOOKUP($T7,Legend!$A$12:$F$19,2,FALSE) -> Haplic Calcisols | V7: =VLOOKUP($T7,Legend!$A$12:$F$19,3,FALSE) -> Calcisol | W7: =VLOOKUP($T7,Legend!$A$12:$F$19,4,FALSE) -> Calcareous soil | X7: =VLOOKUP($T7,Legend!$A$12:$F$19,5,FALSE) -> Moderate | Y7: =VLOOKUP($T7,Legend!$A$12:$F$19,6,FALSE) -> 3 | Z7: Cretaceous-Tertiary sedimentary | AA7: CSIF-L | AB7: 1 | AC7: Probable establecimiento termal; mosaicos, mármol, tubos; termas con dos bassins y conducción
A8: 6 | B8: 43.181 | C8: Sidi al Khafi / Henchir Sidi al Khafi | D8: 617999.59 | E8: 3999077.6 | F8: 3.977 | G8: villa | H8: medium | I8: 658.35522 | J8: 32.903106 | K8: 440.06721 | L8: 440.06721 | M8: 440.06721 | N8: 440.06721 | O8: SH | P8: =VLOOKUP($O8,Legend!$H$12:$K$15,2,FALSE) -> Medium hill | Q8: =VLOOKUP($O8,Legend!$H$12:$K$15,3,FALSE) -> Low | R8: =VLOOKUP($O8,Legend!$H$12:$K$15,4,FALSE) -> 1 | S8: SO1 | T8: CMc | U8: =VLOOKUP($T8,Legend!$A$12:$F$19,2,FALSE) -> Calcaric Cambisols | V8: =VLOOKUP($T8,Legend!$A$12:$F$19,3,FALSE) -> Cambisol | W8: =VLOOKUP($T8,Legend!$A$12:$F$19,4,FALSE) -> Moderately developed calcareous soil | X8: =VLOOKUP($T8,Legend!$A$12:$F$19,5,FALSE) -> Moderate | Y8: =VLOOKUP($T8,Legend!$A$12:$F$19,6,FALSE) -> 3 | Z8: Cretaceous-Tertiary sedimentary | AA8: CSIF-L | AB8: 1 | AC8: Dos cisternas, canalización, pozo, muro semicircular, enduit étanche, mosaico, tubos
A9: 7 | B9: 43.131 | C9: Henchir Ad-Diwan | D9: 623233 | E9: 4001280.2 | F9: 1.178 | G9: farm | H9: high | I9: 832.29027 | J9: 1412.1245 | K9: 520.23967 | L9: 596.86149 | M9: 584.07585 | N9: 949.33753 | O9: LP | P9: =VLOOKUP($O9,Legend!$H$12:$K$15,2,FALSE) -> Plain | Q9: =VLOOKUP($O9,Legend!$H$12:$K$15,3,FALSE) -> Moderate-high | R9: =VLOOKUP($O9,Legend!$H$12:$K$15,4,FALSE) -> 3 | S9: SO1 | T9: CMc | U9: =VLOOKUP($T9,Legend!$A$12:$F$19,2,FALSE) -> Calcaric Cambisols | V9: =VLOOKUP($T9,Legend!$A$12:$F$19,3,FALSE) -> Cambisol | W9: =VLOOKUP($T9,Legend!$A$12:$F$19,4,FALSE) -> Moderately developed calcareous soil | X9: =VLOOKUP($T9,Legend!$A$12:$F$19,5,FALSE) -> Moderate | Y9: =VLOOKUP($T9,Legend!$A$12:$F$19,6,FALSE) -> 3 | Z9: Cretaceous-Tertiary sedimentary | AA9: CSIF-L | AB9: 1 | AC9: El inventario identifica explícitamente una Ferme; muro de 1 m, pavimento con enduit étanche y otro de mosaico
A10: 8 | B10: 43.022 | C10: Oued Awinet al Hjal | D10: 624771.26 | E10: 4009188.7 | F10: 2.93 | G10: farm | H10: high | I10: 546.26185 | J10: 3121.0666 | K10: 72.173978 | L10: 72.173958 | M10: 72.173978 | N10: 72.173978 | O10: SH | P10: =VLOOKUP($O10,Legend!$H$12:$K$15,2,FALSE) -> Medium hill | Q10: =VLOOKUP($O10,Legend!$H$12:$K$15,3,FALSE) -> Low | R10: =VLOOKUP($O10,Legend!$H$12:$K$15,4,FALSE) -> 1 | S10: SO1 | T10: CMc | U10: =VLOOKUP($T10,Legend!$A$12:$F$19,2,FALSE) -> Calcaric Cambisols | V10: =VLOOKUP($T10,Legend!$A$12:$F$19,3,FALSE) -> Cambisol | W10: =VLOOKUP($T10,Legend!$A$12:$F$19,4,FALSE) -> Moderately developed calcareous soil | X10: =VLOOKUP($T10,Legend!$A$12:$F$19,5,FALSE) -> Moderate | Y10: =VLOOKUP($T10,Legend!$A$12:$F$19,6,FALSE) -> 3 | Z10: Cretaceous-Tertiary sedimentary | AA10: CSIF-L | AB10: 1 | AC10: Restos de dos huileries
A11: 9 | B11: 43.024 | C11: Bir Khammouma | D11: 625381.92 | E11: 4009781.9 | F11: 1.243 | G11: farm | H11: high | I11: 1137.0025 | J11: 2788.6077 | K11: 239.45542 | L11: 288.29568 | M11: 278.51614 | N11: 651.98598 | O11: SH | P11: =VLOOKUP($O11,Legend!$H$12:$K$15,2,FALSE) -> Medium hill | Q11: =VLOOKUP($O11,Legend!$H$12:$K$15,3,FALSE) -> Low | R11: =VLOOKUP($O11,Legend!$H$12:$K$15,4,FALSE) -> 1 | S11: SO1 | T11: CMc | U11: =VLOOKUP($T11,Legend!$A$12:$F$19,2,FALSE) -> Calcaric Cambisols | V11: =VLOOKUP($T11,Legend!$A$12:$F$19,3,FALSE) -> Cambisol | W11: =VLOOKUP($T11,Legend!$A$12:$F$19,4,FALSE) -> Moderately developed calcareous soil | X11: =VLOOKUP($T11,Legend!$A$12:$F$19,5,FALSE) -> Moderate | Y11: =VLOOKUP($T11,Legend!$A$12:$F$19,6,FALSE) -> 3 | Z11: Cretaceous-Tertiary sedimentary | AA11: CSIF-L | AB11: 1 | AC11: Huilerie, opus africanum, maie, contrapeso; además enduit étanche y teselas
A12: 10 | B12: 43.035 | C12: Oued Jadarmi | D12: 628728.97 | E12: 4009396.5 | F12: 1.263 | G12: farm | H12: high | I12: 234.26089 | J12: 577.76146 | K12: 252.21151 | L12: 252.21155 | M12: 412.82762 | N12: 494.65097 | O12: LV | P12: =VLOOKUP($O12,Legend!$H$12:$K$15,2,FALSE) -> Valley floor | Q12: =VLOOKUP($O12,Legend!$H$12:$K$15,3,FALSE) -> High | R12: =VLOOKUP($O12,Legend!$H$12:$K$15,4,FALSE) -> 4 | S12: UF | T12: GLe | U12: =VLOOKUP($T12,Legend!$A$12:$F$19,2,FALSE) -> Eutric Gleysols | V12: =VLOOKUP($T12,Legend!$A$12:$F$19,3,FALSE) -> Gleysol | W12: =VLOOKUP($T12,Legend!$A$12:$F$19,4,FALSE) -> Poor drainage / waterlogging | X12: =VLOOKUP($T12,Legend!$A$12:$F$19,5,FALSE) -> Low | Y12: =VLOOKUP($T12,Legend!$A$12:$F$19,6,FALSE) -> 2 | Z12: Unconsolidated | AA12: U-H | AB12: 4 | AC12: Elementos de huilerie en place; maie, mortier de trapetum, bassin de décantation, contrapeso
A13: 11 | B13: 43.09 | C13: Aïn al Hargh | D13: 609707.75 | E13: 4006750.6 | F13: 2.6 | G13: farm | H13: high | I13: 938.60931 | J13: 5287.6149 | K13: 67.957438 | L13: 200.2488 | M13: 357.0693 | N13: 357.0693 | O13: SH | P13: =VLOOKUP($O13,Legend!$H$12:$K$15,2,FALSE) -> Medium hill | Q13: =VLOOKUP($O13,Legend!$H$12:$K$15,3,FALSE) -> Low | R13: =VLOOKUP($O13,Legend!$H$12:$K$15,4,FALSE) -> 1 | S13: SO1 | T13: CMc | U13: =VLOOKUP($T13,Legend!$A$12:$F$19,2,FALSE) -> Calcaric Cambisols | V13: =VLOOKUP($T13,Legend!$A$12:$F$19,3,FALSE) -> Cambisol | W13: =VLOOKUP($T13,Legend!$A$12:$F$19,4,FALSE) -> Moderately developed calcareous soil | X13: =VLOOKUP($T13,Legend!$A$12:$F$19,5,FALSE) -> Moderate | Y13: =VLOOKUP($T13,Legend!$A$12:$F$19,6,FALSE) -> 3 | Z13: Cretaceous-Tertiary sedimentary | AA13: CSIF-M | AB13: 3 | AC13: Restos de huilerie: maie, contrapeso, instalación hidráulica, harpes
A14: 12 | B14: 43.159 | C14: Aïn Swissifa | D14: 617660.65 | E14: 4005369.3 | F14: 0.659 | G14: farm | H14: high | I14: 1256.9172 | J14: 2308.9697 | K14: 614.57726 | L14: 614.57729 | M14: 614.57726 | N14: 992.90902 | O14: SH | P14: =VLOOKUP($O14,Legend!$H$12:$K$15,2,FALSE) -> Medium hill | Q14: =VLOOKUP($O14,Legend!$H$12:$K$15,3,FALSE) -> Low | R14: =VLOOKUP($O14,Legend!$H$12:$K$15,4,FALSE) -> 1 | S14: SO1 | T14: CMc | U14: =VLOOKUP($T14,Legend!$A$12:$F$19,2,FALSE) -> Calcaric Cambisols | V14: =VLOOKUP($T14,Legend!$A$12:$F$19,3,FALSE) -> Cambisol | W14: =VLOOKUP($T14,Legend!$A$12:$F$19,4,FALSE) -> Moderately developed calcareous soil | X14: =VLOOKUP($T14,Legend!$A$12:$F$19,5,FALSE) -> Moderate | Y14: =VLOOKUP($T14,Legend!$A$12:$F$19,6,FALSE) -> 3 | Z14: Cretaceous-Tertiary sedimentary | AA14: CSIF-L | AB14: 1 | AC14: Huilerie; dos jumelles en place, pavimento de mosaico, meule
A15: 13 | B15: 74.041 | C15: El Maklouba | D15: 681141 | E15: 3923540 | F15: 0 | G15: villa | H15: high | I15: 186.98919 | J15: 4128.9063 | K15: 112.23881 | L15: 112.23879 | M15: 112.23881 | N15: 353.81195 | O15: LP | P15: =VLOOKUP($O15,Legend!$H$12:$K$15,2,FALSE) -> Plain | Q15: =VLOOKUP($O15,Legend!$H$12:$K$15,3,FALSE) -> Moderate-high | R15: =VLOOKUP($O15,Legend!$H$12:$K$15,4,FALSE) -> 3 | S15: UF | T15: FLe | U15: =VLOOKUP($T15,Legend!$A$12:$F$19,2,FALSE) -> Eutric Fluvisols | V15: =VLOOKUP($T15,Legend!$A$12:$F$19,3,FALSE) -> Fluvisol | W15: =VLOOKUP($T15,Legend!$A$12:$F$19,4,FALSE) -> Alluvial soil; generally fertile | X15: =VLOOKUP($T15,Legend!$A$12:$F$19,5,FALSE) -> High | Y15: =VLOOKUP($T15,Legend!$A$12:$F$19,6,FALSE) -> 4 | Z15: Cretaceous-Tertiary sedimentary | AA15: CSIF-M | AB15: 3
A16: 14 | B16: 75.042 | C16: Eddouamis | D16: 678772 | E16: 3925619 | F16: 25 | G16: villa | H16: high | I16: 1806.2153 | J16: 2226.8223 | K16: 223.63063 | L16: 538.18975 | M16: 538.18977 | N16: 1497.1138 | O16: LP | P16: =VLOOKUP($O16,Legend!$H$12:$K$15,2,FALSE) -> Plain | Q16: =VLOOKUP($O16,Legend!$H$12:$K$15,3,FALSE) -> Moderate-high | R16: =VLOOKUP($O16,Legend!$H$12:$K$15,4,FALSE) -> 3 | S16: UF | T16: FLe | U16: =VLOOKUP($T16,Legend!$A$12:$F$19,2,FALSE) -> Eutric Fluvisols | V16: =VLOOKUP($T16,Legend!$A$12:$F$19,3,FALSE) -> Fluvisol | W16: =VLOOKUP($T16,Legend!$A$12:$F$19,4,FALSE) -> Alluvial soil; generally fertile | X16: =VLOOKUP($T16,Legend!$A$12:$F$19,5,FALSE) -> High | Y16: =VLOOKUP($T16,Legend!$A$12:$F$19,6,FALSE) -> 4 | Z16: Unconsolidated | AA16: U-H | AB16: 4
A17: 15 | B17: 74.066-67/69-71 | C17: Henchir El Merigueb | D17: 663786 | E17: 3917982 | F17: 10 | G17: villa | H17: high | I17: 351.62941 | J17: 1447.5286 | K17: 57.350916 | L17: 57.35092 | M17: 57.350916 | N17: 57.350916 | O17: LP | P17: =VLOOKUP($O17,Legend!$H$12:$K$15,2,FALSE) -> Plain | Q17: =VLOOKUP($O17,Legend!$H$12:$K$15,3,FALSE) -> Moderate-high | R17: =VLOOKUP($O17,Legend!$H$12:$K$15,4,FALSE) -> 3 | S17: UF | T17: FLe | U17: =VLOOKUP($T17,Legend!$A$12:$F$19,2,FALSE) -> Eutric Fluvisols | V17: =VLOOKUP($T17,Legend!$A$12:$F$19,3,FALSE) -> Fluvisol | W17: =VLOOKUP($T17,Legend!$A$12:$F$19,4,FALSE) -> Alluvial soil; generally fertile | X17: =VLOOKUP($T17,Legend!$A$12:$F$19,5,FALSE) -> High | Y17: =VLOOKUP($T17,Legend!$A$12:$F$19,6,FALSE) -> 4 | Z17: Unconsolidated | AA17: U-H | AB17: 4
A18: 16 | B18: 74.078–74.080 | C18: Henchir El Hanichate | D18: 668294 | E18: 3905969 | F18: 50 | G18: villa | H18: high | I18: 1418.7564 | J18: 1858.5772 | K18: 85.963969 | L18: 218.18804 | M18: 331.33649 | N18: 614.84538 | O18: LP | P18: =VLOOKUP($O18,Legend!$H$12:$K$15,2,FALSE) -> Plain | Q18: =VLOOKUP($O18,Legend!$H$12:$K$15,3,FALSE) -> Moderate-high | R18: =VLOOKUP($O18,Legend!$H$12:$K$15,4,FALSE) -> 3 | S18: SO2 | T18: CLp | U18: =VLOOKUP($T18,Legend!$A$12:$F$19,2,FALSE) -> Petric Calcisols | V18: =VLOOKUP($T18,Legend!$A$12:$F$19,3,FALSE) -> Calcisol | W18: =VLOOKUP($T18,Legend!$A$12:$F$19,4,FALSE) -> Petrocalcic hardpan / restricted rooting | X18: =VLOOKUP($T18,Legend!$A$12:$F$19,5,FALSE) -> Low | Y18: =VLOOKUP($T18,Legend!$A$12:$F$19,6,FALSE) -> 2 | Z18: Unconsolidated | AA18: U-H | AB18: 4
A19: 17 | B19: 74.031 | C19: Henchir Merbess | D19: 672708 | E19: 3926915 | F19: 10 | G19: villa | H19: medium | I19: 1726.877 | J19: 987.08056 | K19: 29.69766 | L19: 29.697693 | M19: 29.69766 | N19: 29.69766 | O19: LP | P19: =VLOOKUP($O19,Legend!$H$12:$K$15,2,FALSE) -> Plain | Q19: =VLOOKUP($O19,Legend!$H$12:$K$15,3,FALSE) -> Moderate-high | R19: =VLOOKUP($O19,Legend!$H$12:$K$15,4,FALSE) -> 3 | S19: SO2 | T19: CLl | U19: =VLOOKUP($T19,Legend!$A$12:$F$19,2,FALSE) -> Luvic Calcisols | V19: =VLOOKUP($T19,Legend!$A$12:$F$19,3,FALSE) -> Calcisol | W19: =VLOOKUP($T19,Legend!$A$12:$F$19,4,FALSE) -> Calcareous soil with clay accumulation | X19: =VLOOKUP($T19,Legend!$A$12:$F$19,5,FALSE) -> Moderate | Y19: =VLOOKUP($T19,Legend!$A$12:$F$19,6,FALSE) -> 3 | Z19: Unconsolidated | AA19: U-H | AB19: 4
A20: 18 | B20: 74.010-74.011 | C20: Henchir Bou Chebih | D20: 669247 | E20: 3922482 | F20: 10 | G20: villa | H20: medium | I20: 19.313045 | J20: 1273.7787 | K20: 2.011753 | L20: 2.011763 | M20: 2.011753 | N20: 2.011753 | O20: LP | P20: =VLOOKUP($O20,Legend!$H$12:$K$15,2,FALSE) -> Plain | Q20: =VLOOKUP($O20,Legend!$H$12:$K$15,3,FALSE) -> Moderate-high | R20: =VLOOKUP($O20,Legend!$H$12:$K$15,4,FALSE) -> 3 | S20: UF | T20: FLe | U20: =VLOOKUP($T20,Legend!$A$12:$F$19,2,FALSE) -> Eutric Fluvisols | V20: =VLOOKUP($T20,Legend!$A$12:$F$19,3,FALSE) -> Fluvisol | W20: =VLOOKUP($T20,Legend!$A$12:$F$19,4,FALSE) -> Alluvial soil; generally fertile | X20: =VLOOKUP($T20,Legend!$A$12:$F$19,5,FALSE) -> High | Y20: =VLOOKUP($T20,Legend!$A$12:$F$19,6,FALSE) -> 4 | Z20: Unconsolidated | AA20: U-H | AB20: 4
A21: 19 | B21: 74.007 | C21: Sidi El Khafi | D21: 667904 | E21: 3932773 | F21: N/D | G21: farm | H21: high | I21: 743.27763 | J21: 3012.2663 | K21: 39.128587 | L21: 488.86931 | M21: 544.8717 | N21: 826.79169 | O21: LP | P21: =VLOOKUP($O21,Legend!$H$12:$K$15,2,FALSE) -> Plain | Q21: =VLOOKUP($O21,Legend!$H$12:$K$15,3,FALSE) -> Moderate-high | R21: =VLOOKUP($O21,Legend!$H$12:$K$15,4,FALSE) -> 3 | S21: UF | T21: FLe | U21: =VLOOKUP($T21,Legend!$A$12:$F$19,2,FALSE) -> Eutric Fluvisols | V21: =VLOOKUP($T21,Legend!$A$12:$F$19,3,FALSE) -> Fluvisol | W21: =VLOOKUP($T21,Legend!$A$12:$F$19,4,FALSE) -> Alluvial soil; generally fertile | X21: =VLOOKUP($T21,Legend!$A$12:$F$19,5,FALSE) -> High | Y21: =VLOOKUP($T21,Legend!$A$12:$F$19,6,FALSE) -> 4 | Z21: Cretaceous-Tertiary sedimentary | AA21: CSIF-M | AB21: 3
A22: 20 | B22: 74.021 | C22: Henchir Echbilette | D22: 676613 | E22: 3932052 | F22: 0.05 | G22: farm | H22: high | I22: 659.39018 | J22: 4334.0089 | K22: 74.79555 | L22: 74.795516 | M22: 74.79555 | N22: 339.9569 | O22: LP | P22: =VLOOKUP($O22,Legend!$H$12:$K$15,2,FALSE) -> Plain | Q22: =VLOOKUP($O22,Legend!$H$12:$K$15,3,FALSE) -> Moderate-high | R22: =VLOOKUP($O22,Legend!$H$12:$K$15,4,FALSE) -> 3 | S22: SO2 | T22: CLl | U22: =VLOOKUP($T22,Legend!$A$12:$F$19,2,FALSE) -> Luvic Calcisols | V22: =VLOOKUP($T22,Legend!$A$12:$F$19,3,FALSE) -> Calcisol | W22: =VLOOKUP($T22,Legend!$A$12:$F$19,4,FALSE) -> Calcareous soil with clay accumulation | X22: =VLOOKUP($T22,Legend!$A$12:$F$19,5,FALSE) -> Moderate | Y22: =VLOOKUP($T22,Legend!$A$12:$F$19,6,FALSE) -> 3 | Z22: Unconsolidated | AA22: U-H | AB22: 4
A23: 21 | B23: 74.028 | C23: Bir El Araba (Essaguia) | D23: 673788 | E23: 3929175 | F23: 35 | G23: farm | H23: high | I23: 2485.8735 | J23: 2782.3243 | K23: 240.80289 | L23: 240.80288 | M23: 240.80289 | N23: 240.3155 | O23: LP | P23: =VLOOKUP($O23,Legend!$H$12:$K$15,2,FALSE) -> Plain | Q23: =VLOOKUP($O23,Legend!$H$12:$K$15,3,FALSE) -> Moderate-high | R23: =VLOOKUP($O23,Legend!$H$12:$K$15,4,FALSE) -> 3 | S23: SO2 | T23: CLl | U23: =VLOOKUP($T23,Legend!$A$12:$F$19,2,FALSE) -> Luvic Calcisols | V23: =VLOOKUP($T23,Legend!$A$12:$F$19,3,FALSE) -> Calcisol | W23: =VLOOKUP($T23,Legend!$A$12:$F$19,4,FALSE) -> Calcareous soil with clay accumulation | X23: =VLOOKUP($T23,Legend!$A$12:$F$19,5,FALSE) -> Moderate | Y23: =VLOOKUP($T23,Legend!$A$12:$F$19,6,FALSE) -> 3 | Z23: Unconsolidated | AA23: U-H | AB23: 4
A24: 22 | B24: 74.035 | C24: N/D | D24: 675837 | E24: 3923792 | F24: 2 | G24: farm | H24: high | I24: 626.69129 | J24: 2932.0589 | K24: 134.55662 | L24: 248.6741 | M24: 671.02929 | N24: 976.5688 | O24: LP | P24: =VLOOKUP($O24,Legend!$H$12:$K$15,2,FALSE) -> Plain | Q24: =VLOOKUP($O24,Legend!$H$12:$K$15,3,FALSE) -> Moderate-high | R24: =VLOOKUP($O24,Legend!$H$12:$K$15,4,FALSE) -> 3 | S24: UF | T24: FLe | U24: =VLOOKUP($T24,Legend!$A$12:$F$19,2,FALSE) -> Eutric Fluvisols | V24: =VLOOKUP($T24,Legend!$A$12:$F$19,3,FALSE) -> Fluvisol | W24: =VLOOKUP($T24,Legend!$A$12:$F$19,4,FALSE) -> Alluvial soil; generally fertile | X24: =VLOOKUP($T24,Legend!$A$12:$F$19,5,FALSE) -> High | Y24: =VLOOKUP($T24,Legend!$A$12:$F$19,6,FALSE) -> 4 | Z24: Cretaceous-Tertiary sedimentary | AA24: CSIF-M | AB24: 3
A25: 23 | B25: 74.036 | C25: El Kherba | D25: 674548 | E25: 3922580 | F25: 0.16 | G25: farm | H25: high | I25: 13.085805 | J25: 3655.7045 | K25: 43.145679 | L25: 43.145709 | M25: 43.145679 | N25: 43.145679 | O25: LP | P25: =VLOOKUP($O25,Legend!$H$12:$K$15,2,FALSE) -> Plain | Q25: =VLOOKUP($O25,Legend!$H$12:$K$15,3,FALSE) -> Moderate-high | R25: =VLOOKUP($O25,Legend!$H$12:$K$15,4,FALSE) -> 3 | S25: SO2 | T25: CLl | U25: =VLOOKUP($T25,Legend!$A$12:$F$19,2,FALSE) -> Luvic Calcisols | V25: =VLOOKUP($T25,Legend!$A$12:$F$19,3,FALSE) -> Calcisol | W25: =VLOOKUP($T25,Legend!$A$12:$F$19,4,FALSE) -> Calcareous soil with clay accumulation | X25: =VLOOKUP($T25,Legend!$A$12:$F$19,5,FALSE) -> Moderate | Y25: =VLOOKUP($T25,Legend!$A$12:$F$19,6,FALSE) -> 3 | Z25: Unconsolidated | AA25: U-H | AB25: 4
A26: 24 | B26: 74.161 | C26: Sidi Maatallah / El Argoub | D26: 668929 | E26: 3913277 | F26: N/D | G26: farm | H26: medium | I26: 1938.7774 | J26: 1681.0636 | K26: 585.37804 | L26: 860.02853 | M26: 860.0285 | N26: 1776.2505 | O26: LP | P26: =VLOOKUP($O26,Legend!$H$12:$K$15,2,FALSE) -> Plain | Q26: =VLOOKUP($O26,Legend!$H$12:$K$15,3,FALSE) -> Moderate-high | R26: =VLOOKUP($O26,Legend!$H$12:$K$15,4,FALSE) -> 3 | S26: SO1 | T26: CLp | U26: =VLOOKUP($T26,Legend!$A$12:$F$19,2,FALSE) -> Petric Calcisols | V26: =VLOOKUP($T26,Legend!$A$12:$F$19,3,FALSE) -> Calcisol | W26: =VLOOKUP($T26,Legend!$A$12:$F$19,4,FALSE) -> Petrocalcic hardpan / restricted rooting | X26: =VLOOKUP($T26,Legend!$A$12:$F$19,5,FALSE) -> Low | Y26: =VLOOKUP($T26,Legend!$A$12:$F$19,6,FALSE) -> 2 | Z26: Cretaceous-Tertiary sedimentary | AA26: CSIF-M | AB26: 3
A27: 25 | B27: 74.186 | C27: Sidi Ali El Jarij | D27: 672974 | E27: 3919565 | F27: 1 | G27: farm | H27: medium | I27: 2970.9338 | J27: 3517.1336 | K27: 529.85804 | L27: 533.2522 | M27: 533.25225 | N27: 1123.1214 | O27: LP | P27: =VLOOKUP($O27,Legend!$H$12:$K$15,2,FALSE) -> Plain | Q27: =VLOOKUP($O27,Legend!$H$12:$K$15,3,FALSE) -> Moderate-high | R27: =VLOOKUP($O27,Legend!$H$12:$K$15,4,FALSE) -> 3 | S27: SO2 | T27: CLl | U27: =VLOOKUP($T27,Legend!$A$12:$F$19,2,FALSE) -> Luvic Calcisols | V27: =VLOOKUP($T27,Legend!$A$12:$F$19,3,FALSE) -> Calcisol | W27: =VLOOKUP($T27,Legend!$A$12:$F$19,4,FALSE) -> Calcareous soil with clay accumulation | X27: =VLOOKUP($T27,Legend!$A$12:$F$19,5,FALSE) -> Moderate | Y27: =VLOOKUP($T27,Legend!$A$12:$F$19,6,FALSE) -> 3 | Z27: Cretaceous-Tertiary sedimentary | AA27: CSIF-M | AB27: 3
A28: 26 | B28: 74.22 | C28: Henchir El Kherba | D28: 677998 | E28: 3922711 | F28: 1.5 | G28: farm | H28: medium | I28: 912.9593 | J28: 4690.9797 | K28: 206.83806 | L28: 277.88182 | M28: 277.88184 | N28: 277.88184 | O28: LP | P28: =VLOOKUP($O28,Legend!$H$12:$K$15,2,FALSE) -> Plain | Q28: =VLOOKUP($O28,Legend!$H$12:$K$15,3,FALSE) -> Moderate-high | R28: =VLOOKUP($O28,Legend!$H$12:$K$15,4,FALSE) -> 3 | S28: UF | T28: FLe | U28: =VLOOKUP($T28,Legend!$A$12:$F$19,2,FALSE) -> Eutric Fluvisols | V28: =VLOOKUP($T28,Legend!$A$12:$F$19,3,FALSE) -> Fluvisol | W28: =VLOOKUP($T28,Legend!$A$12:$F$19,4,FALSE) -> Alluvial soil; generally fertile | X28: =VLOOKUP($T28,Legend!$A$12:$F$19,5,FALSE) -> High | Y28: =VLOOKUP($T28,Legend!$A$12:$F$19,6,FALSE) -> 4 | Z28: Cretaceous-Tertiary sedimentary | AA28: CSIF-M | AB28: 3
A29: 27 | B29: 72.061 | C29: N/D | D29: 605508 | E29: 3930908 | F29: 9 | G29: villa | H29: high | I29: 334.85284 | J29: 2071.3724 | K29: 156.60333 | L29: 156.60334 | M29: 156.60333 | N29: 156.60333 | O29: LP | P29: =VLOOKUP($O29,Legend!$H$12:$K$15,2,FALSE) -> Plain | Q29: =VLOOKUP($O29,Legend!$H$12:$K$15,3,FALSE) -> Moderate-high | R29: =VLOOKUP($O29,Legend!$H$12:$K$15,4,FALSE) -> 3 | S29: UL | T29: SNk | U29: =VLOOKUP($T29,Legend!$A$12:$F$19,2,FALSE) -> Calcic Solonetz | V29: =VLOOKUP($T29,Legend!$A$12:$F$19,3,FALSE) -> Solonetz | W29: =VLOOKUP($T29,Legend!$A$12:$F$19,4,FALSE) -> Sodicity / structural constraint | X29: =VLOOKUP($T29,Legend!$A$12:$F$19,5,FALSE) -> Very low | Y29: =VLOOKUP($T29,Legend!$A$12:$F$19,6,FALSE) -> 1 | Z29: Unconsolidated | AA29: U-H | AB29: 4 | AC29: Restos de huilerie; bassin con enduit étanche y cuvette de décantation; dos contrepoids; edificio destruido con abside, conducción de agua y bassin mosaïqué; abundante sigillata
A30: 28 | B30: 72.051 | C30: Hamadet Tarfaïat | D30: 624956 | E30: 3925884 | F30: 9 | G30: villa | H30: medium | I30: 1678.5608 | J30: 1627.7016 | K30: 9.973397 | L30: 417.0716 | M30: 417.07161 | N30: 522.42741 | O30: LP | P30: =VLOOKUP($O30,Legend!$H$12:$K$15,2,FALSE) -> Plain | Q30: =VLOOKUP($O30,Legend!$H$12:$K$15,3,FALSE) -> Moderate-high | R30: =VLOOKUP($O30,Legend!$H$12:$K$15,4,FALSE) -> 3 | S30: SO2 | T30: CLl | U30: =VLOOKUP($T30,Legend!$A$12:$F$19,2,FALSE) -> Luvic Calcisols | V30: =VLOOKUP($T30,Legend!$A$12:$F$19,3,FALSE) -> Calcisol | W30: =VLOOKUP($T30,Legend!$A$12:$F$19,4,FALSE) -> Calcareous soil with clay accumulation | X30: =VLOOKUP($T30,Legend!$A$12:$F$19,5,FALSE) -> Moderate | Y30: =VLOOKUP($T30,Legend!$A$12:$F$19,6,FALSE) -> 3 | Z30: Unconsolidated | AA30: U-H | AB30: 4 | AC30: Monumento enterrado con bassin semi-circulaire/oblong con mosaico polícromo; pilettes d’hypocaustes; bloques con encoche; monedas; cerámica muy abundante
A31: 29 | B31: 72.068 | C31: N/D | D31: 624474 | E31: 3923879 | F31: N/D | G31: villa | H31: medium | I31: 2345.9981 | J31: 155.18152 | K31: 7.922356 | L31: 64.8617 | M31: 64.86169 | N31: 191.36531 | O31: LP | P31: =VLOOKUP($O31,Legend!$H$12:$K$15,2,FALSE) -> Plain | Q31: =VLOOKUP($O31,Legend!$H$12:$K$15,3,FALSE) -> Moderate-high | R31: =VLOOKUP($O31,Legend!$H$12:$K$15,4,FALSE) -> 3 | S31: SO2 | T31: CLl | U31: =VLOOKUP($T31,Legend!$A$12:$F$19,2,FALSE) -> Luvic Calcisols | V31: =VLOOKUP($T31,Legend!$A$12:$F$19,3,FALSE) -> Calcisol | W31: =VLOOKUP($T31,Legend!$A$12:$F$19,4,FALSE) -> Calcareous soil with clay accumulation | X31: =VLOOKUP($T31,Legend!$A$12:$F$19,5,FALSE) -> Moderate | Y31: =VLOOKUP($T31,Legend!$A$12:$F$19,6,FALSE) -> 3 | Z31: Unconsolidated | AA31: U-H | AB31: 4 | AC31: Edificio en blocage con enduit étanche grueso; abside; parte de bassin; posibles restos de hypocaustes; teselas, mármol y cerámica fina
A32: 30 | B32: 72.087 | C32: N/D | D32: 607231 | E32: 3922823 | F32: 4.5 | G32: villa | H32: medium | I32: 3651.4052 | J32: 641.81159 | K32: 680.61403 | L32: 680.61405 | M32: 680.61403 | N32: 692.33265 | O32: LP | P32: =VLOOKUP($O32,Legend!$H$12:$K$15,2,FALSE) -> Plain | Q32: =VLOOKUP($O32,Legend!$H$12:$K$15,3,FALSE) -> Moderate-high | R32: =VLOOKUP($O32,Legend!$H$12:$K$15,4,FALSE) -> 3 | S32: SO2 | T32: CLl | U32: =VLOOKUP($T32,Legend!$A$12:$F$19,2,FALSE) -> Luvic Calcisols | V32: =VLOOKUP($T32,Legend!$A$12:$F$19,3,FALSE) -> Calcisol | W32: =VLOOKUP($T32,Legend!$A$12:$F$19,4,FALSE) -> Calcareous soil with clay accumulation | X32: =VLOOKUP($T32,Legend!$A$12:$F$19,5,FALSE) -> Moderate | Y32: =VLOOKUP($T32,Legend!$A$12:$F$19,6,FALSE) -> 3 | Z32: Cretaceous-Tertiary sedimentary | AA32: CSIF-M | AB32: 3 | AC32: Varias estructuras en moellons; pavimento “béton blanchâtre”; bassin de 6 × 3.2 m con enduit étanche y conducción en terracota; el texto lo considera probablemente un édifice thermal
A33: 31 | B33: 72.114 | C33: N/D | D33: 613398 | E33: 3921128 | F33: 9 | G33: villa | H33: medium | I33: 2610.1005 | J33: 882.23558 | K33: 140.00549 | L33: 140.0055 | M33: 140.00549 | N33: 140.00549 | O33: LP | P33: =VLOOKUP($O33,Legend!$H$12:$K$15,2,FALSE) -> Plain | Q33: =VLOOKUP($O33,Legend!$H$12:$K$15,3,FALSE) -> Moderate-high | R33: =VLOOKUP($O33,Legend!$H$12:$K$15,4,FALSE) -> 3 | S33: SO1 | T33: CLp | U33: =VLOOKUP($T33,Legend!$A$12:$F$19,2,FALSE) -> Petric Calcisols | V33: =VLOOKUP($T33,Legend!$A$12:$F$19,3,FALSE) -> Calcisol | W33: =VLOOKUP($T33,Legend!$A$12:$F$19,4,FALSE) -> Petrocalcic hardpan / restricted rooting | X33: =VLOOKUP($T33,Legend!$A$12:$F$19,5,FALSE) -> Low | Y33: =VLOOKUP($T33,Legend!$A$12:$F$19,6,FALSE) -> 2 | Z33: Cretaceous-Tertiary sedimentary | AA33: CSIF-M | AB33: 3 | AC33: Afloramientos de estructuras, bassins con enduit, puits antique, densidad alta de cerámica; junto a ello un mausolée cuadrado bien conservado y otros destruidos
A34: 32 | B34: 72.073 | C34: N/D | D34: 620730 | E34: 3923145 | F34: 4 | G34: farm | H34: medium | I34: 2612.8318 | J34: 2426.3983 | K34: 220.89089 | L34: 221.08401 | M34: 401.33072 | N34: 1891.7011 | O34: LP | P34: =VLOOKUP($O34,Legend!$H$12:$K$15,2,FALSE) -> Plain | Q34: =VLOOKUP($O34,Legend!$H$12:$K$15,3,FALSE) -> Moderate-high | R34: =VLOOKUP($O34,Legend!$H$12:$K$15,4,FALSE) -> 3 | S34: SO1 | T34: CLp | U34: =VLOOKUP($T34,Legend!$A$12:$F$19,2,FALSE) -> Petric Calcisols | V34: =VLOOKUP($T34,Legend!$A$12:$F$19,3,FALSE) -> Calcisol | W34: =VLOOKUP($T34,Legend!$A$12:$F$19,4,FALSE) -> Petrocalcic hardpan / restricted rooting | X34: =VLOOKUP($T34,Legend!$A$12:$F$19,5,FALSE) -> Low | Y34: =VLOOKUP($T34,Legend!$A$12:$F$19,6,FALSE) -> 2 | Z34: Unconsolidated | AA34: U-H | AB34: 4 | AC34: Un mamelón con ratés de cuisson probable four à potier; otro con bassin revestido de mosaico polícromo, canalización cerámica y fragmentos de hypocaustes
A35: 33 | B35: 72.064 | C35: Henchir Bou Setta | D35: 614120 | E35: 3924185 | F35: 0.65 | G35: farm | H35: high | I35: 1411.4527 | J35: 2221.1243 | K35: 237.69032 | L35: 237.69032 | M35: 237.69032 | N35: 496.84417 | O35: LP | P35: =VLOOKUP($O35,Legend!$H$12:$K$15,2,FALSE) -> Plain | Q35: =VLOOKUP($O35,Legend!$H$12:$K$15,3,FALSE) -> Moderate-high | R35: =VLOOKUP($O35,Legend!$H$12:$K$15,4,FALSE) -> 3 | S35: SO1 | T35: CLp | U35: =VLOOKUP($T35,Legend!$A$12:$F$19,2,FALSE) -> Petric Calcisols | V35: =VLOOKUP($T35,Legend!$A$12:$F$19,3,FALSE) -> Calcisol | W35: =VLOOKUP($T35,Legend!$A$12:$F$19,4,FALSE) -> Petrocalcic hardpan / restricted rooting | X35: =VLOOKUP($T35,Legend!$A$12:$F$19,5,FALSE) -> Low | Y35: =VLOOKUP($T35,Legend!$A$12:$F$19,6,FALSE) -> 2 | Z35: Unconsolidated | AA35: U-H | AB35: 4 | AC35: Bassin circulaire, estructura de llegada/salida de agua, contrepoids d’huilerie, bloque tallado y sigillata en fuerte densidad
A36: 34 | B36: 72.128 | C36: Sidi Mabrouk | D36: 619909 | E36: 3919987 | F36: 1 | G36: farm | H36: high | I36: 2554.9112 | J36: 799.03083 | K36: 578.79274 | L36: 664.71147 | M36: 1065.6353 | N36: 1119.4708 | O36: LP | P36: =VLOOKUP($O36,Legend!$H$12:$K$15,2,FALSE) -> Plain | Q36: =VLOOKUP($O36,Legend!$H$12:$K$15,3,FALSE) -> Moderate-high | R36: =VLOOKUP($O36,Legend!$H$12:$K$15,4,FALSE) -> 3 | S36: SO2 | T36: CLl | U36: =VLOOKUP($T36,Legend!$A$12:$F$19,2,FALSE) -> Luvic Calcisols | V36: =VLOOKUP($T36,Legend!$A$12:$F$19,3,FALSE) -> Calcisol | W36: =VLOOKUP($T36,Legend!$A$12:$F$19,4,FALSE) -> Calcareous soil with clay accumulation | X36: =VLOOKUP($T36,Legend!$A$12:$F$19,5,FALSE) -> Moderate | Y36: =VLOOKUP($T36,Legend!$A$12:$F$19,6,FALSE) -> 3 | Z36: Unconsolidated | AA36: U-H | AB36: 4 | AC36: Restos de edificio en blocage; el autor cree que el sol conservado con enduit étanche sería probablemente el aire de pressage d’une huilerie; además capitel, colonnette y bloques
A37: 35 | B37: 72.017 | C37: Biar Ali Ben Mosbah | D37: 616104 | E37: 3931454 | F37: 4 | G37: farm | H37: medium | I37: 685.40101 | J37: 149.57815 | K37: 515.98868 | L37: 515.99947 | M37: 515.18616 | N37: 1427.0422 | O37: LP | P37: =VLOOKUP($O37,Legend!$H$12:$K$15,2,FALSE) -> Plain | Q37: =VLOOKUP($O37,Legend!$H$12:$K$15,3,FALSE) -> Moderate-high | R37: =VLOOKUP($O37,Legend!$H$12:$K$15,4,FALSE) -> 3 | S37: SO2 | T37: CLl | U37: =VLOOKUP($T37,Legend!$A$12:$F$19,2,FALSE) -> Luvic Calcisols | V37: =VLOOKUP($T37,Legend!$A$12:$F$19,3,FALSE) -> Calcisol | W37: =VLOOKUP($T37,Legend!$A$12:$F$19,4,FALSE) -> Calcareous soil with clay accumulation | X37: =VLOOKUP($T37,Legend!$A$12:$F$19,5,FALSE) -> Moderate | Y37: =VLOOKUP($T37,Legend!$A$12:$F$19,6,FALSE) -> 3 | Z37: Unconsolidated | AA37: U-H | AB37: 4 | AC37: Citerne antique de 10 × 4 m, seis puits, numerosos bloques tallados, broyeur, moneda, cerámica fina y común abundante; el sitio continúa al sur de la ruta
A38: 36 | B38: 72.133 | C38: Sidi Amor Ben Bouzid | D38: 624864 | E38: 3919482 | F38: 3 | G38: farm | H38: low | I38: 1602.4268 | J38: 604.89129 | K38: 324.94891 | L38: 324.9489 | M38: 524.23658 | N38: 581.17591 | O38: LP | P38: =VLOOKUP($O38,Legend!$H$12:$K$15,2,FALSE) -> Plain | Q38: =VLOOKUP($O38,Legend!$H$12:$K$15,3,FALSE) -> Moderate-high | R38: =VLOOKUP($O38,Legend!$H$12:$K$15,4,FALSE) -> 3 | S38: SO2 | T38: CLl | U38: =VLOOKUP($T38,Legend!$A$12:$F$19,2,FALSE) -> Luvic Calcisols | V38: =VLOOKUP($T38,Legend!$A$12:$F$19,3,FALSE) -> Calcisol | W38: =VLOOKUP($T38,Legend!$A$12:$F$19,4,FALSE) -> Calcareous soil with clay accumulation | X38: =VLOOKUP($T38,Legend!$A$12:$F$19,5,FALSE) -> Moderate | Y38: =VLOOKUP($T38,Legend!$A$12:$F$19,6,FALSE) -> 3 | Z38: Unconsolidated | AA38: U-H | AB38: 4 | AC38: Sitio antiguo alrededor del marabout; gran citerne con arcos internos y otra segunda citerne enterrada; cerámica fina muy abundante al este
A39: 37 | B39: 64.054 | C39: Henchir Ben Maati / Henchir Ben Mustapha | D39: 626224 | E39: 3945999 | F39: 0.5 | G39: villa | H39: high | I39: 1099.5713 | J39: 4892.3428 | K39: 241.72189 | L39: 241.7219 | M39: 241.72189 | N39: 814.46146 | O39: LD | P39: =VLOOKUP($O39,Legend!$H$12:$K$15,2,FALSE) -> Depression | Q39: =VLOOKUP($O39,Legend!$H$12:$K$15,3,FALSE) -> Low-moderate | R39: =VLOOKUP($O39,Legend!$H$12:$K$15,4,FALSE) -> 2 | S39: UL | T39: SNk | U39: =VLOOKUP($T39,Legend!$A$12:$F$19,2,FALSE) -> Calcic Solonetz | V39: =VLOOKUP($T39,Legend!$A$12:$F$19,3,FALSE) -> Solonetz | W39: =VLOOKUP($T39,Legend!$A$12:$F$19,4,FALSE) -> Sodicity / structural constraint | X39: =VLOOKUP($T39,Legend!$A$12:$F$19,5,FALSE) -> Very low | Y39: =VLOOKUP($T39,Legend!$A$12:$F$19,6,FALSE) -> 1 | Z39: Unconsolidated | AA39: U-H | AB39: 4 | AC39: Dos edificios; uno mucho más grande y compacto; tégulas, pilettes d’hypocauste, mosaico polícromo, cerámica fina y sigillata. El autor dice además que conserva habitación + thermes privés y que la cisterna asociada es 064.055.
